<?xml version="1.0" ?>
<robot name="example" xmlns:xacro="http://www.ros.org/wiki/xacro">

<xacro:include filename="$(find example_description)/urdf/materials.xacro" />
<xacro:include filename="$(find example_description)/urdf/sensors.xacro" />
<xacro:include filename="$(find example_description)/urdf/example.gazebo" />
<link name="base_link">
  <inertial>
    <origin xyz="0.0 0.0 0.2010582738066993" rpy="0 0 0"/>
    <mass value="283.90880895747955"/>
    <inertia ixx="5.956824" iyy="5.956839" izz="4.239584" ixy="0.0" iyz="0.0" ixz="0.0"/>
  </inertial>
  <visual>
    <origin xyz="0 0 0" rpy="0 0 0"/>
    <geometry>
      <mesh filename="file://$(find example_description)/meshes/base_link.stl" scale="0.001 0.001 0.001"/>
    </geometry>
    <material name="silver"/>
  </visual>
  <collision>
    <origin xyz="0 0 0" rpy="0 0 0"/>
    <geometry>
      <mesh filename="file://$(find example_description)/meshes/base_link.stl" scale="0.001 0.001 0.001"/>
    </geometry>
  </collision>
</link>

<link name="kinect_DCAM_1">
  <inertial>
    <origin xyz="0.024999999999999994 -1.7763568394002505e-17 0.10999999999999999" rpy="0 0 0"/>
    <mass value="1.5699999999999998"/>
    <inertia ixx="0.001518" iyy="0.000536" izz="0.001635" ixy="0.0" iyz="0.0" ixz="0.0"/>
  </inertial>
  <visual>
    <origin xyz="-0.15 0.0 -0.2" rpy="0 0 0"/>
    <geometry>
      <mesh filename="file://$(find example_description)/meshes/kinect_DCAM_1.stl" scale="0.001 0.001 0.001"/>
    </geometry>
    <material name="silver"/>
  </visual>
  <collision>
    <origin xyz="-0.15 0.0 -0.2" rpy="0 0 0"/>
    <geometry>
      <mesh filename="file://$(find example_description)/meshes/kinect_DCAM_1.stl" scale="0.001 0.001 0.001"/>
    </geometry>
  </collision>
</link>

<link name="zed_CAM_1">
  <inertial>
    <origin xyz="0.024999999999999994 -1.70530256582424e-17 0.0" rpy="0 0 0"/>
    <mass value="1.5700000000000003"/>
    <inertia ixx="0.001518" iyy="0.000536" izz="0.001635" ixy="-0.0" iyz="0.0" ixz="-0.0"/>
  </inertial>
  <visual>
    <origin xyz="-0.15 0.0 -0.4" rpy="0 0 0"/>
    <geometry>
      <mesh filename="file://$(find example_description)/meshes/zed_CAM_1.stl" scale="0.001 0.001 0.001"/>
    </geometry>
    <material name="silver"/>
  </visual>
  <collision>
    <origin xyz="-0.15 0.0 -0.4" rpy="0 0 0"/>
    <geometry>
      <mesh filename="file://$(find example_description)/meshes/zed_CAM_1.stl" scale="0.001 0.001 0.001"/>
    </geometry>
  </collision>
</link>

<link name="dummy_GPS_1">
  <inertial>
    <origin xyz="0.0 0.0 0.004999999999999893" rpy="0 0 0"/>
    <mass value="0.05548838024402973"/>
    <inertia ixx="4e-06" iyy="4e-06" izz="6e-06" ixy="0.0" iyz="-0.0" ixz="-0.0"/>
  </inertial>
  <visual>
    <origin xyz="-0.15 -0.15 -0.4" rpy="0 0 0"/>
    <geometry>
      <mesh filename="file://$(find example_description)/meshes/dummy_GPS_1.stl" scale="0.001 0.001 0.001"/>
    </geometry>
    <material name="silver"/>
  </visual>
  <collision>
    <origin xyz="-0.15 -0.15 -0.4" rpy="0 0 0"/>
    <geometry>
      <mesh filename="file://$(find example_description)/meshes/dummy_GPS_1.stl" scale="0.001 0.001 0.001"/>
    </geometry>
  </collision>
</link>

<link name="bosch_IMU_1">
  <inertial>
    <origin xyz="0.0 -2.7755575615628914e-17 0.004999999999999893" rpy="0 0 0"/>
    <mass value="0.05548838024402973"/>
    <inertia ixx="4e-06" iyy="4e-06" izz="6e-06" ixy="-0.0" iyz="0.0" ixz="-0.0"/>
  </inertial>
  <visual>
    <origin xyz="-0.15 0.15 -0.4" rpy="0 0 0"/>
    <geometry>
      <mesh filename="file://$(find example_description)/meshes/bosch_IMU_1.stl" scale="0.001 0.001 0.001"/>
    </geometry>
    <material name="silver"/>
  </visual>
  <collision>
    <origin xyz="-0.15 0.15 -0.4" rpy="0 0 0"/>
    <geometry>
      <mesh filename="file://$(find example_description)/meshes/bosch_IMU_1.stl" scale="0.001 0.001 0.001"/>
    </geometry>
  </collision>
</link>

<link name="link_two_1">
  <inertial>
    <origin xyz="-3.3306690738754696e-16 -0.007584281310081709 0.0" rpy="0 0 0"/>
    <mass value="2.179866965429678"/>
    <inertia ixx="0.00435" iyy="0.007857" izz="0.003614" ixy="-0.0" iyz="0.0" ixz="0.0"/>
  </inertial>
  <visual>
    <origin xyz="-0.11 0.545058 -0.2" rpy="0 0 0"/>
    <geometry>
      <mesh filename="file://$(find example_description)/meshes/link_two_1.stl" scale="0.001 0.001 0.001"/>
    </geometry>
    <material name="silver"/>
  </visual>
  <collision>
    <origin xyz="-0.11 0.545058 -0.2" rpy="0 0 0"/>
    <geometry>
      <mesh filename="file://$(find example_description)/meshes/link_two_1.stl" scale="0.001 0.001 0.001"/>
    </geometry>
  </collision>
</link>

<link name="link_one_1">
  <inertial>
    <origin xyz="0.04213147063000812 -0.0798425366049435 -5.551115123125783e-17" rpy="0 0 0"/>
    <mass value="5.22101345866791"/>
    <inertia ixx="0.022983" iyy="0.002744" izz="0.023374" ixy="0.001441" iyz="0.0" ixz="-0.0"/>
  </inertial>
  <visual>
    <origin xyz="-0.064498 0.35 -0.2" rpy="0 0 0"/>
    <geometry>
      <mesh filename="file://$(find example_description)/meshes/link_one_1.stl" scale="0.001 0.001 0.001"/>
    </geometry>
    <material name="silver"/>
  </visual>
  <collision>
    <origin xyz="-0.064498 0.35 -0.2" rpy="0 0 0"/>
    <geometry>
      <mesh filename="file://$(find example_description)/meshes/link_one_1.stl" scale="0.001 0.001 0.001"/>
    </geometry>
  </collision>
</link>

<link name="link_zero_1">
  <inertial>
    <origin xyz="0.008360783142984612 -0.11790581557971438 -5.551115123125783e-17" rpy="0 0 0"/>
    <mass value="5.39430977186155"/>
    <inertia ixx="0.024271" iyy="0.003723" izz="0.025567" ixy="0.003631" iyz="0.0" ixz="0.0"/>
  </inertial>
  <visual>
    <origin xyz="-0.0 0.15 -0.2" rpy="0 0 0"/>
    <geometry>
      <mesh filename="file://$(find example_description)/meshes/link_zero_1.stl" scale="0.001 0.001 0.001"/>
    </geometry>
    <material name="silver"/>
  </visual>
  <collision>
    <origin xyz="-0.0 0.15 -0.2" rpy="0 0 0"/>
    <geometry>
      <mesh filename="file://$(find example_description)/meshes/link_zero_1.stl" scale="0.001 0.001 0.001"/>
    </geometry>
  </collision>
</link>

<link name="hokuyo_L2D_1">
  <inertial>
    <origin xyz="-4.483699816452154e-18 0.0 0.024999999999999967" rpy="0 0 0"/>
    <mass value="0.9952067629951794"/>
    <inertia ixx="0.000382" iyy="0.000454" izz="0.000422" ixy="0.0" iyz="0.0" ixz="0.0"/>
  </inertial>
  <visual>
    <origin xyz="-0.0 -0.0 -0.46" rpy="0 0 0"/>
    <geometry>
      <mesh filename="file://$(find example_description)/meshes/hokuyo_L2D_1.stl" scale="0.001 0.001 0.001"/>
    </geometry>
    <material name="silver"/>
  </visual>
  <collision>
    <origin xyz="-0.0 -0.0 -0.46" rpy="0 0 0"/>
    <geometry>
      <mesh filename="file://$(find example_description)/meshes/hokuyo_L2D_1.stl" scale="0.001 0.001 0.001"/>
    </geometry>
  </collision>
</link>

<link name="velodyne_L3D_1">
  <inertial>
    <origin xyz="-4.483699816452154e-18 4.483699816452154e-18 0.02499999999999991" rpy="0 0 0"/>
    <mass value="0.9952067629951794"/>
    <inertia ixx="0.000382" iyy="0.000454" izz="0.000422" ixy="-0.0" iyz="0.0" ixz="0.0"/>
  </inertial>
  <visual>
    <origin xyz="-0.0 -0.0 -0.51" rpy="0 0 0"/>
    <geometry>
      <mesh filename="file://$(find example_description)/meshes/velodyne_L3D_1.stl" scale="0.001 0.001 0.001"/>
    </geometry>
    <material name="silver"/>
  </visual>
  <collision>
    <origin xyz="-0.0 -0.0 -0.51" rpy="0 0 0"/>
    <geometry>
      <mesh filename="file://$(find example_description)/meshes/velodyne_L3D_1.stl" scale="0.001 0.001 0.001"/>
    </geometry>
  </collision>
</link>

<link name="end_effector_1">
  <inertial>
    <origin xyz="-3.608224830031759e-16 -0.008265577366620036 0.0" rpy="0 0 0"/>
    <mass value="7.050473843052527"/>
    <inertia ixx="0.005894" iyy="0.183465" izz="0.177891" ixy="0.0" iyz="-0.0" ixz="0.0"/>
  </inertial>
  <visual>
    <origin xyz="-0.11 0.556792 -0.2" rpy="0 0 0"/>
    <geometry>
      <mesh filename="file://$(find example_description)/meshes/end_effector_1.stl" scale="0.001 0.001 0.001"/>
    </geometry>
    <material name="silver"/>
  </visual>
  <collision>
    <origin xyz="-0.11 0.556792 -0.2" rpy="0 0 0"/>
    <geometry>
      <mesh filename="file://$(find example_description)/meshes/end_effector_1.stl" scale="0.001 0.001 0.001"/>
    </geometry>
  </collision>
</link>

<joint name="cam_joint" type="revolute">
  <origin xyz="0.15 0.0 0.2" rpy="0 0 0"/>
  <parent link="base_link"/>
  <child link="kinect_DCAM_1"/>
  <axis xyz="1.0 0.0 0.0"/>
  <limit upper="0.0" lower="0.0" effort="100" velocity="100"/>
</joint>

<link name="kinect_optical">
<joint name="kinect_optical_joint" type="fixed">
    <parent link="kinect_DCAM_1"/>
    <child link="kinect_optical"/>
    <origin xyz="0 0 0" rpy="-1.5708 0 -1.5708"/>
</joint>

<joint name="dcam_joint" type="revolute">
  <origin xyz="0.15 0.0 0.4" rpy="0 0 0"/>
  <parent link="base_link"/>
  <child link="zed_CAM_1"/>
  <axis xyz="1.0 0.0 0.0"/>
  <limit upper="0.0" lower="0.0" effort="100" velocity="100"/>
</joint>

<joint name="gps_joint" type="revolute">
  <origin xyz="0.15 0.15 0.4" rpy="0 0 0"/>
  <parent link="base_link"/>
  <child link="dummy_GPS_1"/>
  <axis xyz="0.0 0.0 1.0"/>
  <limit upper="0.0" lower="0.0" effort="100" velocity="100"/>
</joint>

<joint name="imu_joint" type="revolute">
  <origin xyz="0.15 -0.15 0.4" rpy="0 0 0"/>
  <parent link="base_link"/>
  <child link="bosch_IMU_1"/>
  <axis xyz="0.0 0.0 1.0"/>
  <limit upper="0.0" lower="0.0" effort="100" velocity="100"/>
</joint>

<joint name="link_two_joint" type="revolute">
  <origin xyz="0.045502 -0.195058 0.0" rpy="0 0 0"/>
  <parent link="link_one_1"/>
  <child link="link_two_1"/>
  <axis xyz="0.0 -1.0 0.0"/>
  <limit upper="6.283185" lower="0.0" effort="100" velocity="100"/>
</joint>

<joint name="link_one_joint" type="revolute">
  <origin xyz="0.064498 -0.2 0.0" rpy="0 0 0"/>
  <parent link="link_zero_1"/>
  <child link="link_one_1"/>
  <axis xyz="1.0 0.0 0.0"/>
  <limit upper="1.570796" lower="-1.570796" effort="100" velocity="100"/>
</joint>

<joint name="link_zero_joint" type="revolute">
  <origin xyz="0.0 -0.15 0.2" rpy="0 0 0"/>
  <parent link="base_link"/>
  <child link="link_zero_1"/>
  <axis xyz="0.0 -1.0 0.0"/>
  <limit upper="3.141593" lower="0.0" effort="100" velocity="100"/>
</joint>

<joint name="l2d_joint" type="continuous">
  <origin xyz="0.0 0.0 0.46" rpy="0 0 0"/>
  <parent link="base_link"/>
  <child link="hokuyo_L2D_1"/>
  <axis xyz="0.0 0.0 1.0"/>
</joint>

<joint name="l3d_joint" type="continuous">
  <origin xyz="0.0 0.0 0.05" rpy="0 0 0"/>
  <parent link="hokuyo_L2D_1"/>
  <child link="velodyne_L3D_1"/>
  <axis xyz="0.0 0.0 1.0"/>
</joint>

<joint name="end_effector_joint" type="prismatic">
  <origin xyz="0.0 -0.011734 0.0" rpy="0 0 0"/>
  <parent link="link_two_1"/>
  <child link="end_effector_1"/>
  <axis xyz="1.0 0.0 0.0"/>
  <limit upper="0.2" lower="-0.2" effort="100" velocity="100"/>
</joint>

</robot>
